2020-08-04 13:06:07,100 : CRITICAL :: APM:Copter V3.3 (d6053245)
2020-08-04 13:06:07,101 : CRITICAL :: Frame: QUAD
2020-08-04 13:06:07,521 : CRITICAL :: Calibrating barometer
2020-08-04 13:06:09,727 : CRITICAL :: Initialising APM...
2020-08-04 13:06:12,005 : CRITICAL :: barometer calibration complete
2020-08-04 13:06:12,006 : CRITICAL :: GROUND START
2020-08-04 13:06:22,044 : ERROR :: Job "read_and_send_data (trigger: interval[0:00:01], next run at: 2020-08-04 13:06:23 +0545)" raised an exception
Traceback (most recent call last):
  File "/home/abhish/anaconda3/envs/xbee/lib/python3.6/site-packages/apscheduler/executors/base.py", line 125, in run_job
    retval = job.func(*job.args, **job.kwargs)
  File "drone_communication.py", line 147, in read_and_send_data
    print("Alt:",_location.alt)
NameError: name '_location' is not defined
2020-08-04 13:06:23,045 : ERROR :: Job "read_and_send_data (trigger: interval[0:00:01], next run at: 2020-08-04 13:06:23 +0545)" raised an exception
Traceback (most recent call last):
  File "/home/abhish/anaconda3/envs/xbee/lib/python3.6/site-packages/apscheduler/executors/base.py", line 125, in run_job
    retval = job.func(*job.args, **job.kwargs)
  File "drone_communication.py", line 147, in read_and_send_data
    print("Alt:",_location.alt)
NameError: name '_location' is not defined
2020-08-04 13:06:24,045 : ERROR :: Job "read_and_send_data (trigger: interval[0:00:01], next run at: 2020-08-04 13:06:24 +0545)" raised an exception
Traceback (most recent call last):
  File "/home/abhish/anaconda3/envs/xbee/lib/python3.6/site-packages/apscheduler/executors/base.py", line 125, in run_job
    retval = job.func(*job.args, **job.kwargs)
  File "drone_communication.py", line 147, in read_and_send_data
    print("Alt:",_location.alt)
NameError: name '_location' is not defined
2020-08-04 13:06:25,046 : ERROR :: Job "read_and_send_data (trigger: interval[0:00:01], next run at: 2020-08-04 13:06:26 +0545)" raised an exception
Traceback (most recent call last):
  File "/home/abhish/anaconda3/envs/xbee/lib/python3.6/site-packages/apscheduler/executors/base.py", line 125, in run_job
    retval = job.func(*job.args, **job.kwargs)
  File "drone_communication.py", line 147, in read_and_send_data
    print("Alt:",_location.alt)
NameError: name '_location' is not defined
2020-08-04 13:06:26,044 : ERROR :: Job "read_and_send_data (trigger: interval[0:00:01], next run at: 2020-08-04 13:06:26 +0545)" raised an exception
Traceback (most recent call last):
  File "/home/abhish/anaconda3/envs/xbee/lib/python3.6/site-packages/apscheduler/executors/base.py", line 125, in run_job
    retval = job.func(*job.args, **job.kwargs)
  File "drone_communication.py", line 147, in read_and_send_data
    print("Alt:",_location.alt)
NameError: name '_location' is not defined
2020-08-04 13:06:27,046 : ERROR :: Job "read_and_send_data (trigger: interval[0:00:01], next run at: 2020-08-04 13:06:27 +0545)" raised an exception
Traceback (most recent call last):
  File "/home/abhish/anaconda3/envs/xbee/lib/python3.6/site-packages/apscheduler/executors/base.py", line 125, in run_job
    retval = job.func(*job.args, **job.kwargs)
  File "drone_communication.py", line 147, in read_and_send_data
    print("Alt:",_location.alt)
NameError: name '_location' is not defined
2020-08-04 13:06:28,046 : ERROR :: Job "read_and_send_data (trigger: interval[0:00:01], next run at: 2020-08-04 13:06:28 +0545)" raised an exception
Traceback (most recent call last):
  File "/home/abhish/anaconda3/envs/xbee/lib/python3.6/site-packages/apscheduler/executors/base.py", line 125, in run_job
    retval = job.func(*job.args, **job.kwargs)
  File "drone_communication.py", line 147, in read_and_send_data
    print("Alt:",_location.alt)
NameError: name '_location' is not defined
2020-08-04 13:06:29,046 : ERROR :: Job "read_and_send_data (trigger: interval[0:00:01], next run at: 2020-08-04 13:06:29 +0545)" raised an exception
Traceback (most recent call last):
  File "/home/abhish/anaconda3/envs/xbee/lib/python3.6/site-packages/apscheduler/executors/base.py", line 125, in run_job
    retval = job.func(*job.args, **job.kwargs)
  File "drone_communication.py", line 147, in read_and_send_data
    print("Alt:",_location.alt)
NameError: name '_location' is not defined
2020-08-04 13:06:30,046 : ERROR :: Job "read_and_send_data (trigger: interval[0:00:01], next run at: 2020-08-04 13:06:30 +0545)" raised an exception
Traceback (most recent call last):
  File "/home/abhish/anaconda3/envs/xbee/lib/python3.6/site-packages/apscheduler/executors/base.py", line 125, in run_job
    retval = job.func(*job.args, **job.kwargs)
  File "drone_communication.py", line 147, in read_and_send_data
    print("Alt:",_location.alt)
NameError: name '_location' is not defined
2020-08-04 13:06:31,045 : ERROR :: Job "read_and_send_data (trigger: interval[0:00:01], next run at: 2020-08-04 13:06:31 +0545)" raised an exception
Traceback (most recent call last):
  File "/home/abhish/anaconda3/envs/xbee/lib/python3.6/site-packages/apscheduler/executors/base.py", line 125, in run_job
    retval = job.func(*job.args, **job.kwargs)
  File "drone_communication.py", line 147, in read_and_send_data
    print("Alt:",_location.alt)
NameError: name '_location' is not defined
2020-08-04 13:06:32,045 : ERROR :: Job "read_and_send_data (trigger: interval[0:00:01], next run at: 2020-08-04 13:06:33 +0545)" raised an exception
Traceback (most recent call last):
  File "/home/abhish/anaconda3/envs/xbee/lib/python3.6/site-packages/apscheduler/executors/base.py", line 125, in run_job
    retval = job.func(*job.args, **job.kwargs)
  File "drone_communication.py", line 147, in read_and_send_data
    print("Alt:",_location.alt)
NameError: name '_location' is not defined
2020-08-04 13:06:33,044 : ERROR :: Job "read_and_send_data (trigger: interval[0:00:01], next run at: 2020-08-04 13:06:34 +0545)" raised an exception
Traceback (most recent call last):
  File "/home/abhish/anaconda3/envs/xbee/lib/python3.6/site-packages/apscheduler/executors/base.py", line 125, in run_job
    retval = job.func(*job.args, **job.kwargs)
  File "drone_communication.py", line 147, in read_and_send_data
    print("Alt:",_location.alt)
NameError: name '_location' is not defined
2020-08-04 13:06:34,044 : ERROR :: Job "read_and_send_data (trigger: interval[0:00:01], next run at: 2020-08-04 13:06:35 +0545)" raised an exception
Traceback (most recent call last):
  File "/home/abhish/anaconda3/envs/xbee/lib/python3.6/site-packages/apscheduler/executors/base.py", line 125, in run_job
    retval = job.func(*job.args, **job.kwargs)
  File "drone_communication.py", line 147, in read_and_send_data
    print("Alt:",_location.alt)
NameError: name '_location' is not defined
2020-08-04 13:06:35,044 : ERROR :: Job "read_and_send_data (trigger: interval[0:00:01], next run at: 2020-08-04 13:06:36 +0545)" raised an exception
Traceback (most recent call last):
  File "/home/abhish/anaconda3/envs/xbee/lib/python3.6/site-packages/apscheduler/executors/base.py", line 125, in run_job
    retval = job.func(*job.args, **job.kwargs)
  File "drone_communication.py", line 147, in read_and_send_data
    print("Alt:",_location.alt)
NameError: name '_location' is not defined
2020-08-04 13:06:36,043 : ERROR :: Job "read_and_send_data (trigger: interval[0:00:01], next run at: 2020-08-04 13:06:37 +0545)" raised an exception
Traceback (most recent call last):
  File "/home/abhish/anaconda3/envs/xbee/lib/python3.6/site-packages/apscheduler/executors/base.py", line 125, in run_job
    retval = job.func(*job.args, **job.kwargs)
  File "drone_communication.py", line 147, in read_and_send_data
    print("Alt:",_location.alt)
NameError: name '_location' is not defined
2020-08-04 13:06:37,044 : ERROR :: Job "read_and_send_data (trigger: interval[0:00:01], next run at: 2020-08-04 13:06:38 +0545)" raised an exception
Traceback (most recent call last):
  File "/home/abhish/anaconda3/envs/xbee/lib/python3.6/site-packages/apscheduler/executors/base.py", line 125, in run_job
    retval = job.func(*job.args, **job.kwargs)
  File "drone_communication.py", line 147, in read_and_send_data
    print("Alt:",_location.alt)
NameError: name '_location' is not defined
2020-08-04 13:06:38,043 : ERROR :: Job "read_and_send_data (trigger: interval[0:00:01], next run at: 2020-08-04 13:06:39 +0545)" raised an exception
Traceback (most recent call last):
  File "/home/abhish/anaconda3/envs/xbee/lib/python3.6/site-packages/apscheduler/executors/base.py", line 125, in run_job
    retval = job.func(*job.args, **job.kwargs)
  File "drone_communication.py", line 147, in read_and_send_data
    print("Alt:",_location.alt)
NameError: name '_location' is not defined
2020-08-04 13:06:39,043 : ERROR :: Job "read_and_send_data (trigger: interval[0:00:01], next run at: 2020-08-04 13:06:40 +0545)" raised an exception
Traceback (most recent call last):
  File "/home/abhish/anaconda3/envs/xbee/lib/python3.6/site-packages/apscheduler/executors/base.py", line 125, in run_job
    retval = job.func(*job.args, **job.kwargs)
  File "drone_communication.py", line 147, in read_and_send_data
    print("Alt:",_location.alt)
NameError: name '_location' is not defined
2020-08-04 13:06:40,044 : ERROR :: Job "read_and_send_data (trigger: interval[0:00:01], next run at: 2020-08-04 13:06:41 +0545)" raised an exception
Traceback (most recent call last):
  File "/home/abhish/anaconda3/envs/xbee/lib/python3.6/site-packages/apscheduler/executors/base.py", line 125, in run_job
    retval = job.func(*job.args, **job.kwargs)
  File "drone_communication.py", line 147, in read_and_send_data
    print("Alt:",_location.alt)
NameError: name '_location' is not defined
2020-08-04 13:06:41,044 : ERROR :: Job "read_and_send_data (trigger: interval[0:00:01], next run at: 2020-08-04 13:06:42 +0545)" raised an exception
Traceback (most recent call last):
  File "/home/abhish/anaconda3/envs/xbee/lib/python3.6/site-packages/apscheduler/executors/base.py", line 125, in run_job
    retval = job.func(*job.args, **job.kwargs)
  File "drone_communication.py", line 147, in read_and_send_data
    print("Alt:",_location.alt)
NameError: name '_location' is not defined
2020-08-04 13:06:42,044 : ERROR :: Job "read_and_send_data (trigger: interval[0:00:01], next run at: 2020-08-04 13:06:43 +0545)" raised an exception
Traceback (most recent call last):
  File "/home/abhish/anaconda3/envs/xbee/lib/python3.6/site-packages/apscheduler/executors/base.py", line 125, in run_job
    retval = job.func(*job.args, **job.kwargs)
  File "drone_communication.py", line 147, in read_and_send_data
    print("Alt:",_location.alt)
NameError: name '_location' is not defined
2020-08-04 13:06:43,044 : ERROR :: Job "read_and_send_data (trigger: interval[0:00:01], next run at: 2020-08-04 13:06:44 +0545)" raised an exception
Traceback (most recent call last):
  File "/home/abhish/anaconda3/envs/xbee/lib/python3.6/site-packages/apscheduler/executors/base.py", line 125, in run_job
    retval = job.func(*job.args, **job.kwargs)
  File "drone_communication.py", line 147, in read_and_send_data
    print("Alt:",_location.alt)
NameError: name '_location' is not defined
2020-08-04 13:06:44,043 : ERROR :: Job "read_and_send_data (trigger: interval[0:00:01], next run at: 2020-08-04 13:06:45 +0545)" raised an exception
Traceback (most recent call last):
  File "/home/abhish/anaconda3/envs/xbee/lib/python3.6/site-packages/apscheduler/executors/base.py", line 125, in run_job
    retval = job.func(*job.args, **job.kwargs)
  File "drone_communication.py", line 147, in read_and_send_data
    print("Alt:",_location.alt)
NameError: name '_location' is not defined
2020-08-04 13:06:45,043 : ERROR :: Job "read_and_send_data (trigger: interval[0:00:01], next run at: 2020-08-04 13:06:46 +0545)" raised an exception
Traceback (most recent call last):
  File "/home/abhish/anaconda3/envs/xbee/lib/python3.6/site-packages/apscheduler/executors/base.py", line 125, in run_job
    retval = job.func(*job.args, **job.kwargs)
  File "drone_communication.py", line 147, in read_and_send_data
    print("Alt:",_location.alt)
NameError: name '_location' is not defined
2020-08-04 13:06:46,044 : ERROR :: Job "read_and_send_data (trigger: interval[0:00:01], next run at: 2020-08-04 13:06:47 +0545)" raised an exception
Traceback (most recent call last):
  File "/home/abhish/anaconda3/envs/xbee/lib/python3.6/site-packages/apscheduler/executors/base.py", line 125, in run_job
    retval = job.func(*job.args, **job.kwargs)
  File "drone_communication.py", line 147, in read_and_send_data
    print("Alt:",_location.alt)
NameError: name '_location' is not defined
2020-08-04 13:06:47,044 : ERROR :: Job "read_and_send_data (trigger: interval[0:00:01], next run at: 2020-08-04 13:06:48 +0545)" raised an exception
Traceback (most recent call last):
  File "/home/abhish/anaconda3/envs/xbee/lib/python3.6/site-packages/apscheduler/executors/base.py", line 125, in run_job
    retval = job.func(*job.args, **job.kwargs)
  File "drone_communication.py", line 147, in read_and_send_data
    print("Alt:",_location.alt)
NameError: name '_location' is not defined
2020-08-04 13:06:48,044 : ERROR :: Job "read_and_send_data (trigger: interval[0:00:01], next run at: 2020-08-04 13:06:49 +0545)" raised an exception
Traceback (most recent call last):
  File "/home/abhish/anaconda3/envs/xbee/lib/python3.6/site-packages/apscheduler/executors/base.py", line 125, in run_job
    retval = job.func(*job.args, **job.kwargs)
  File "drone_communication.py", line 147, in read_and_send_data
    print("Alt:",_location.alt)
NameError: name '_location' is not defined
2020-08-04 13:06:49,044 : ERROR :: Job "read_and_send_data (trigger: interval[0:00:01], next run at: 2020-08-04 13:06:50 +0545)" raised an exception
Traceback (most recent call last):
  File "/home/abhish/anaconda3/envs/xbee/lib/python3.6/site-packages/apscheduler/executors/base.py", line 125, in run_job
    retval = job.func(*job.args, **job.kwargs)
  File "drone_communication.py", line 147, in read_and_send_data
    print("Alt:",_location.alt)
NameError: name '_location' is not defined
2020-08-04 13:06:50,044 : ERROR :: Job "read_and_send_data (trigger: interval[0:00:01], next run at: 2020-08-04 13:06:51 +0545)" raised an exception
Traceback (most recent call last):
  File "/home/abhish/anaconda3/envs/xbee/lib/python3.6/site-packages/apscheduler/executors/base.py", line 125, in run_job
    retval = job.func(*job.args, **job.kwargs)
  File "drone_communication.py", line 147, in read_and_send_data
    print("Alt:",_location.alt)
NameError: name '_location' is not defined
2020-08-04 13:06:51,044 : ERROR :: Job "read_and_send_data (trigger: interval[0:00:01], next run at: 2020-08-04 13:06:52 +0545)" raised an exception
Traceback (most recent call last):
  File "/home/abhish/anaconda3/envs/xbee/lib/python3.6/site-packages/apscheduler/executors/base.py", line 125, in run_job
    retval = job.func(*job.args, **job.kwargs)
  File "drone_communication.py", line 147, in read_and_send_data
    print("Alt:",_location.alt)
NameError: name '_location' is not defined
2020-08-04 13:06:52,044 : ERROR :: Job "read_and_send_data (trigger: interval[0:00:01], next run at: 2020-08-04 13:06:53 +0545)" raised an exception
Traceback (most recent call last):
  File "/home/abhish/anaconda3/envs/xbee/lib/python3.6/site-packages/apscheduler/executors/base.py", line 125, in run_job
    retval = job.func(*job.args, **job.kwargs)
  File "drone_communication.py", line 147, in read_and_send_data
    print("Alt:",_location.alt)
NameError: name '_location' is not defined
2020-08-04 13:06:53,044 : ERROR :: Job "read_and_send_data (trigger: interval[0:00:01], next run at: 2020-08-04 13:06:54 +0545)" raised an exception
Traceback (most recent call last):
  File "/home/abhish/anaconda3/envs/xbee/lib/python3.6/site-packages/apscheduler/executors/base.py", line 125, in run_job
    retval = job.func(*job.args, **job.kwargs)
  File "drone_communication.py", line 147, in read_and_send_data
    print("Alt:",_location.alt)
NameError: name '_location' is not defined
2020-08-04 13:06:54,043 : ERROR :: Job "read_and_send_data (trigger: interval[0:00:01], next run at: 2020-08-04 13:06:55 +0545)" raised an exception
Traceback (most recent call last):
  File "/home/abhish/anaconda3/envs/xbee/lib/python3.6/site-packages/apscheduler/executors/base.py", line 125, in run_job
    retval = job.func(*job.args, **job.kwargs)
  File "drone_communication.py", line 147, in read_and_send_data
    print("Alt:",_location.alt)
NameError: name '_location' is not defined
2020-08-04 13:06:55,043 : ERROR :: Job "read_and_send_data (trigger: interval[0:00:01], next run at: 2020-08-04 13:06:56 +0545)" raised an exception
Traceback (most recent call last):
  File "/home/abhish/anaconda3/envs/xbee/lib/python3.6/site-packages/apscheduler/executors/base.py", line 125, in run_job
    retval = job.func(*job.args, **job.kwargs)
  File "drone_communication.py", line 147, in read_and_send_data
    print("Alt:",_location.alt)
NameError: name '_location' is not defined
2020-08-04 13:06:56,044 : ERROR :: Job "read_and_send_data (trigger: interval[0:00:01], next run at: 2020-08-04 13:06:57 +0545)" raised an exception
Traceback (most recent call last):
  File "/home/abhish/anaconda3/envs/xbee/lib/python3.6/site-packages/apscheduler/executors/base.py", line 125, in run_job
    retval = job.func(*job.args, **job.kwargs)
  File "drone_communication.py", line 147, in read_and_send_data
    print("Alt:",_location.alt)
NameError: name '_location' is not defined
2020-08-04 13:06:57,044 : ERROR :: Job "read_and_send_data (trigger: interval[0:00:01], next run at: 2020-08-04 13:06:58 +0545)" raised an exception
Traceback (most recent call last):
  File "/home/abhish/anaconda3/envs/xbee/lib/python3.6/site-packages/apscheduler/executors/base.py", line 125, in run_job
    retval = job.func(*job.args, **job.kwargs)
  File "drone_communication.py", line 147, in read_and_send_data
    print("Alt:",_location.alt)
NameError: name '_location' is not defined
2020-08-04 13:06:58,044 : ERROR :: Job "read_and_send_data (trigger: interval[0:00:01], next run at: 2020-08-04 13:06:59 +0545)" raised an exception
Traceback (most recent call last):
  File "/home/abhish/anaconda3/envs/xbee/lib/python3.6/site-packages/apscheduler/executors/base.py", line 125, in run_job
    retval = job.func(*job.args, **job.kwargs)
  File "drone_communication.py", line 147, in read_and_send_data
    print("Alt:",_location.alt)
NameError: name '_location' is not defined
2020-08-04 13:06:59,043 : ERROR :: Job "read_and_send_data (trigger: interval[0:00:01], next run at: 2020-08-04 13:07:00 +0545)" raised an exception
Traceback (most recent call last):
  File "/home/abhish/anaconda3/envs/xbee/lib/python3.6/site-packages/apscheduler/executors/base.py", line 125, in run_job
    retval = job.func(*job.args, **job.kwargs)
  File "drone_communication.py", line 147, in read_and_send_data
    print("Alt:",_location.alt)
NameError: name '_location' is not defined
2020-08-04 13:07:00,043 : ERROR :: Job "read_and_send_data (trigger: interval[0:00:01], next run at: 2020-08-04 13:07:01 +0545)" raised an exception
Traceback (most recent call last):
  File "/home/abhish/anaconda3/envs/xbee/lib/python3.6/site-packages/apscheduler/executors/base.py", line 125, in run_job
    retval = job.func(*job.args, **job.kwargs)
  File "drone_communication.py", line 147, in read_and_send_data
    print("Alt:",_location.alt)
NameError: name '_location' is not defined
2020-08-04 13:07:01,044 : ERROR :: Job "read_and_send_data (trigger: interval[0:00:01], next run at: 2020-08-04 13:07:02 +0545)" raised an exception
Traceback (most recent call last):
  File "/home/abhish/anaconda3/envs/xbee/lib/python3.6/site-packages/apscheduler/executors/base.py", line 125, in run_job
    retval = job.func(*job.args, **job.kwargs)
  File "drone_communication.py", line 147, in read_and_send_data
    print("Alt:",_location.alt)
NameError: name '_location' is not defined
2020-08-04 13:07:02,043 : ERROR :: Job "read_and_send_data (trigger: interval[0:00:01], next run at: 2020-08-04 13:07:03 +0545)" raised an exception
Traceback (most recent call last):
  File "/home/abhish/anaconda3/envs/xbee/lib/python3.6/site-packages/apscheduler/executors/base.py", line 125, in run_job
    retval = job.func(*job.args, **job.kwargs)
  File "drone_communication.py", line 147, in read_and_send_data
    print("Alt:",_location.alt)
NameError: name '_location' is not defined
2020-08-04 13:07:03,044 : ERROR :: Job "read_and_send_data (trigger: interval[0:00:01], next run at: 2020-08-04 13:07:04 +0545)" raised an exception
Traceback (most recent call last):
  File "/home/abhish/anaconda3/envs/xbee/lib/python3.6/site-packages/apscheduler/executors/base.py", line 125, in run_job
    retval = job.func(*job.args, **job.kwargs)
  File "drone_communication.py", line 147, in read_and_send_data
    print("Alt:",_location.alt)
NameError: name '_location' is not defined
2020-08-04 13:07:04,044 : ERROR :: Job "read_and_send_data (trigger: interval[0:00:01], next run at: 2020-08-04 13:07:05 +0545)" raised an exception
Traceback (most recent call last):
  File "/home/abhish/anaconda3/envs/xbee/lib/python3.6/site-packages/apscheduler/executors/base.py", line 125, in run_job
    retval = job.func(*job.args, **job.kwargs)
  File "drone_communication.py", line 147, in read_and_send_data
    print("Alt:",_location.alt)
NameError: name '_location' is not defined
2020-08-04 13:07:05,044 : ERROR :: Job "read_and_send_data (trigger: interval[0:00:01], next run at: 2020-08-04 13:07:06 +0545)" raised an exception
Traceback (most recent call last):
  File "/home/abhish/anaconda3/envs/xbee/lib/python3.6/site-packages/apscheduler/executors/base.py", line 125, in run_job
    retval = job.func(*job.args, **job.kwargs)
  File "drone_communication.py", line 147, in read_and_send_data
    print("Alt:",_location.alt)
NameError: name '_location' is not defined
2020-08-04 13:07:06,044 : ERROR :: Job "read_and_send_data (trigger: interval[0:00:01], next run at: 2020-08-04 13:07:07 +0545)" raised an exception
Traceback (most recent call last):
  File "/home/abhish/anaconda3/envs/xbee/lib/python3.6/site-packages/apscheduler/executors/base.py", line 125, in run_job
    retval = job.func(*job.args, **job.kwargs)
  File "drone_communication.py", line 147, in read_and_send_data
    print("Alt:",_location.alt)
NameError: name '_location' is not defined
2020-08-04 13:07:07,044 : ERROR :: Job "read_and_send_data (trigger: interval[0:00:01], next run at: 2020-08-04 13:07:08 +0545)" raised an exception
Traceback (most recent call last):
  File "/home/abhish/anaconda3/envs/xbee/lib/python3.6/site-packages/apscheduler/executors/base.py", line 125, in run_job
    retval = job.func(*job.args, **job.kwargs)
  File "drone_communication.py", line 147, in read_and_send_data
    print("Alt:",_location.alt)
NameError: name '_location' is not defined
2020-08-04 13:07:08,044 : ERROR :: Job "read_and_send_data (trigger: interval[0:00:01], next run at: 2020-08-04 13:07:09 +0545)" raised an exception
Traceback (most recent call last):
  File "/home/abhish/anaconda3/envs/xbee/lib/python3.6/site-packages/apscheduler/executors/base.py", line 125, in run_job
    retval = job.func(*job.args, **job.kwargs)
  File "drone_communication.py", line 147, in read_and_send_data
    print("Alt:",_location.alt)
NameError: name '_location' is not defined
2020-08-04 13:07:09,044 : ERROR :: Job "read_and_send_data (trigger: interval[0:00:01], next run at: 2020-08-04 13:07:10 +0545)" raised an exception
Traceback (most recent call last):
  File "/home/abhish/anaconda3/envs/xbee/lib/python3.6/site-packages/apscheduler/executors/base.py", line 125, in run_job
    retval = job.func(*job.args, **job.kwargs)
  File "drone_communication.py", line 147, in read_and_send_data
    print("Alt:",_location.alt)
NameError: name '_location' is not defined
2020-08-04 13:07:10,043 : ERROR :: Job "read_and_send_data (trigger: interval[0:00:01], next run at: 2020-08-04 13:07:11 +0545)" raised an exception
Traceback (most recent call last):
  File "/home/abhish/anaconda3/envs/xbee/lib/python3.6/site-packages/apscheduler/executors/base.py", line 125, in run_job
    retval = job.func(*job.args, **job.kwargs)
  File "drone_communication.py", line 147, in read_and_send_data
    print("Alt:",_location.alt)
NameError: name '_location' is not defined
2020-08-04 13:07:11,043 : ERROR :: Job "read_and_send_data (trigger: interval[0:00:01], next run at: 2020-08-04 13:07:12 +0545)" raised an exception
Traceback (most recent call last):
  File "/home/abhish/anaconda3/envs/xbee/lib/python3.6/site-packages/apscheduler/executors/base.py", line 125, in run_job
    retval = job.func(*job.args, **job.kwargs)
  File "drone_communication.py", line 147, in read_and_send_data
    print("Alt:",_location.alt)
NameError: name '_location' is not defined
2020-08-04 13:07:12,044 : ERROR :: Job "read_and_send_data (trigger: interval[0:00:01], next run at: 2020-08-04 13:07:13 +0545)" raised an exception
Traceback (most recent call last):
  File "/home/abhish/anaconda3/envs/xbee/lib/python3.6/site-packages/apscheduler/executors/base.py", line 125, in run_job
    retval = job.func(*job.args, **job.kwargs)
  File "drone_communication.py", line 147, in read_and_send_data
    print("Alt:",_location.alt)
NameError: name '_location' is not defined
2020-08-04 13:07:13,043 : ERROR :: Job "read_and_send_data (trigger: interval[0:00:01], next run at: 2020-08-04 13:07:14 +0545)" raised an exception
Traceback (most recent call last):
  File "/home/abhish/anaconda3/envs/xbee/lib/python3.6/site-packages/apscheduler/executors/base.py", line 125, in run_job
    retval = job.func(*job.args, **job.kwargs)
  File "drone_communication.py", line 147, in read_and_send_data
    print("Alt:",_location.alt)
NameError: name '_location' is not defined
2020-08-04 13:07:14,043 : ERROR :: Job "read_and_send_data (trigger: interval[0:00:01], next run at: 2020-08-04 13:07:15 +0545)" raised an exception
Traceback (most recent call last):
  File "/home/abhish/anaconda3/envs/xbee/lib/python3.6/site-packages/apscheduler/executors/base.py", line 125, in run_job
    retval = job.func(*job.args, **job.kwargs)
  File "drone_communication.py", line 147, in read_and_send_data
    print("Alt:",_location.alt)
NameError: name '_location' is not defined
2020-08-04 13:07:15,043 : ERROR :: Job "read_and_send_data (trigger: interval[0:00:01], next run at: 2020-08-04 13:07:16 +0545)" raised an exception
Traceback (most recent call last):
  File "/home/abhish/anaconda3/envs/xbee/lib/python3.6/site-packages/apscheduler/executors/base.py", line 125, in run_job
    retval = job.func(*job.args, **job.kwargs)
  File "drone_communication.py", line 147, in read_and_send_data
    print("Alt:",_location.alt)
NameError: name '_location' is not defined
2020-08-04 13:07:16,044 : ERROR :: Job "read_and_send_data (trigger: interval[0:00:01], next run at: 2020-08-04 13:07:17 +0545)" raised an exception
Traceback (most recent call last):
  File "/home/abhish/anaconda3/envs/xbee/lib/python3.6/site-packages/apscheduler/executors/base.py", line 125, in run_job
    retval = job.func(*job.args, **job.kwargs)
  File "drone_communication.py", line 147, in read_and_send_data
    print("Alt:",_location.alt)
NameError: name '_location' is not defined
2020-08-04 13:07:17,044 : ERROR :: Job "read_and_send_data (trigger: interval[0:00:01], next run at: 2020-08-04 13:07:18 +0545)" raised an exception
Traceback (most recent call last):
  File "/home/abhish/anaconda3/envs/xbee/lib/python3.6/site-packages/apscheduler/executors/base.py", line 125, in run_job
    retval = job.func(*job.args, **job.kwargs)
  File "drone_communication.py", line 147, in read_and_send_data
    print("Alt:",_location.alt)
NameError: name '_location' is not defined
2020-08-04 13:07:18,043 : ERROR :: Job "read_and_send_data (trigger: interval[0:00:01], next run at: 2020-08-04 13:07:19 +0545)" raised an exception
Traceback (most recent call last):
  File "/home/abhish/anaconda3/envs/xbee/lib/python3.6/site-packages/apscheduler/executors/base.py", line 125, in run_job
    retval = job.func(*job.args, **job.kwargs)
  File "drone_communication.py", line 147, in read_and_send_data
    print("Alt:",_location.alt)
NameError: name '_location' is not defined
2020-08-04 13:07:19,043 : ERROR :: Job "read_and_send_data (trigger: interval[0:00:01], next run at: 2020-08-04 13:07:20 +0545)" raised an exception
Traceback (most recent call last):
  File "/home/abhish/anaconda3/envs/xbee/lib/python3.6/site-packages/apscheduler/executors/base.py", line 125, in run_job
    retval = job.func(*job.args, **job.kwargs)
  File "drone_communication.py", line 147, in read_and_send_data
    print("Alt:",_location.alt)
NameError: name '_location' is not defined
2020-08-04 13:07:20,044 : ERROR :: Job "read_and_send_data (trigger: interval[0:00:01], next run at: 2020-08-04 13:07:21 +0545)" raised an exception
Traceback (most recent call last):
  File "/home/abhish/anaconda3/envs/xbee/lib/python3.6/site-packages/apscheduler/executors/base.py", line 125, in run_job
    retval = job.func(*job.args, **job.kwargs)
  File "drone_communication.py", line 147, in read_and_send_data
    print("Alt:",_location.alt)
NameError: name '_location' is not defined
2020-08-04 13:07:21,044 : ERROR :: Job "read_and_send_data (trigger: interval[0:00:01], next run at: 2020-08-04 13:07:22 +0545)" raised an exception
Traceback (most recent call last):
  File "/home/abhish/anaconda3/envs/xbee/lib/python3.6/site-packages/apscheduler/executors/base.py", line 125, in run_job
    retval = job.func(*job.args, **job.kwargs)
  File "drone_communication.py", line 147, in read_and_send_data
    print("Alt:",_location.alt)
NameError: name '_location' is not defined
2020-08-04 13:07:22,044 : ERROR :: Job "read_and_send_data (trigger: interval[0:00:01], next run at: 2020-08-04 13:07:23 +0545)" raised an exception
Traceback (most recent call last):
  File "/home/abhish/anaconda3/envs/xbee/lib/python3.6/site-packages/apscheduler/executors/base.py", line 125, in run_job
    retval = job.func(*job.args, **job.kwargs)
  File "drone_communication.py", line 147, in read_and_send_data
    print("Alt:",_location.alt)
NameError: name '_location' is not defined
2020-08-04 13:07:23,044 : ERROR :: Job "read_and_send_data (trigger: interval[0:00:01], next run at: 2020-08-04 13:07:24 +0545)" raised an exception
Traceback (most recent call last):
  File "/home/abhish/anaconda3/envs/xbee/lib/python3.6/site-packages/apscheduler/executors/base.py", line 125, in run_job
    retval = job.func(*job.args, **job.kwargs)
  File "drone_communication.py", line 147, in read_and_send_data
    print("Alt:",_location.alt)
NameError: name '_location' is not defined
2020-08-04 13:07:24,044 : ERROR :: Job "read_and_send_data (trigger: interval[0:00:01], next run at: 2020-08-04 13:07:25 +0545)" raised an exception
Traceback (most recent call last):
  File "/home/abhish/anaconda3/envs/xbee/lib/python3.6/site-packages/apscheduler/executors/base.py", line 125, in run_job
    retval = job.func(*job.args, **job.kwargs)
  File "drone_communication.py", line 147, in read_and_send_data
    print("Alt:",_location.alt)
NameError: name '_location' is not defined
2020-08-04 13:07:25,044 : ERROR :: Job "read_and_send_data (trigger: interval[0:00:01], next run at: 2020-08-04 13:07:26 +0545)" raised an exception
Traceback (most recent call last):
  File "/home/abhish/anaconda3/envs/xbee/lib/python3.6/site-packages/apscheduler/executors/base.py", line 125, in run_job
    retval = job.func(*job.args, **job.kwargs)
  File "drone_communication.py", line 147, in read_and_send_data
    print("Alt:",_location.alt)
NameError: name '_location' is not defined
2020-08-04 13:07:26,044 : ERROR :: Job "read_and_send_data (trigger: interval[0:00:01], next run at: 2020-08-04 13:07:27 +0545)" raised an exception
Traceback (most recent call last):
  File "/home/abhish/anaconda3/envs/xbee/lib/python3.6/site-packages/apscheduler/executors/base.py", line 125, in run_job
    retval = job.func(*job.args, **job.kwargs)
  File "drone_communication.py", line 147, in read_and_send_data
    print("Alt:",_location.alt)
NameError: name '_location' is not defined
2020-08-04 13:07:27,043 : ERROR :: Job "read_and_send_data (trigger: interval[0:00:01], next run at: 2020-08-04 13:07:28 +0545)" raised an exception
Traceback (most recent call last):
  File "/home/abhish/anaconda3/envs/xbee/lib/python3.6/site-packages/apscheduler/executors/base.py", line 125, in run_job
    retval = job.func(*job.args, **job.kwargs)
  File "drone_communication.py", line 147, in read_and_send_data
    print("Alt:",_location.alt)
NameError: name '_location' is not defined
2020-08-04 13:07:28,044 : ERROR :: Job "read_and_send_data (trigger: interval[0:00:01], next run at: 2020-08-04 13:07:29 +0545)" raised an exception
Traceback (most recent call last):
  File "/home/abhish/anaconda3/envs/xbee/lib/python3.6/site-packages/apscheduler/executors/base.py", line 125, in run_job
    retval = job.func(*job.args, **job.kwargs)
  File "drone_communication.py", line 147, in read_and_send_data
    print("Alt:",_location.alt)
NameError: name '_location' is not defined
2020-08-04 13:07:29,044 : ERROR :: Job "read_and_send_data (trigger: interval[0:00:01], next run at: 2020-08-04 13:07:30 +0545)" raised an exception
Traceback (most recent call last):
  File "/home/abhish/anaconda3/envs/xbee/lib/python3.6/site-packages/apscheduler/executors/base.py", line 125, in run_job
    retval = job.func(*job.args, **job.kwargs)
  File "drone_communication.py", line 147, in read_and_send_data
    print("Alt:",_location.alt)
NameError: name '_location' is not defined
2020-08-04 13:07:30,044 : ERROR :: Job "read_and_send_data (trigger: interval[0:00:01], next run at: 2020-08-04 13:07:31 +0545)" raised an exception
Traceback (most recent call last):
  File "/home/abhish/anaconda3/envs/xbee/lib/python3.6/site-packages/apscheduler/executors/base.py", line 125, in run_job
    retval = job.func(*job.args, **job.kwargs)
  File "drone_communication.py", line 147, in read_and_send_data
    print("Alt:",_location.alt)
NameError: name '_location' is not defined
2020-08-04 13:07:31,044 : ERROR :: Job "read_and_send_data (trigger: interval[0:00:01], next run at: 2020-08-04 13:07:32 +0545)" raised an exception
Traceback (most recent call last):
  File "/home/abhish/anaconda3/envs/xbee/lib/python3.6/site-packages/apscheduler/executors/base.py", line 125, in run_job
    retval = job.func(*job.args, **job.kwargs)
  File "drone_communication.py", line 147, in read_and_send_data
    print("Alt:",_location.alt)
NameError: name '_location' is not defined
2020-08-04 13:07:32,044 : ERROR :: Job "read_and_send_data (trigger: interval[0:00:01], next run at: 2020-08-04 13:07:33 +0545)" raised an exception
Traceback (most recent call last):
  File "/home/abhish/anaconda3/envs/xbee/lib/python3.6/site-packages/apscheduler/executors/base.py", line 125, in run_job
    retval = job.func(*job.args, **job.kwargs)
  File "drone_communication.py", line 147, in read_and_send_data
    print("Alt:",_location.alt)
NameError: name '_location' is not defined
2020-08-04 13:07:33,043 : ERROR :: Job "read_and_send_data (trigger: interval[0:00:01], next run at: 2020-08-04 13:07:34 +0545)" raised an exception
Traceback (most recent call last):
  File "/home/abhish/anaconda3/envs/xbee/lib/python3.6/site-packages/apscheduler/executors/base.py", line 125, in run_job
    retval = job.func(*job.args, **job.kwargs)
  File "drone_communication.py", line 147, in read_and_send_data
    print("Alt:",_location.alt)
NameError: name '_location' is not defined
2020-08-04 13:07:34,044 : ERROR :: Job "read_and_send_data (trigger: interval[0:00:01], next run at: 2020-08-04 13:07:35 +0545)" raised an exception
Traceback (most recent call last):
  File "/home/abhish/anaconda3/envs/xbee/lib/python3.6/site-packages/apscheduler/executors/base.py", line 125, in run_job
    retval = job.func(*job.args, **job.kwargs)
  File "drone_communication.py", line 147, in read_and_send_data
    print("Alt:",_location.alt)
NameError: name '_location' is not defined
2020-08-04 13:07:35,044 : ERROR :: Job "read_and_send_data (trigger: interval[0:00:01], next run at: 2020-08-04 13:07:36 +0545)" raised an exception
Traceback (most recent call last):
  File "/home/abhish/anaconda3/envs/xbee/lib/python3.6/site-packages/apscheduler/executors/base.py", line 125, in run_job
    retval = job.func(*job.args, **job.kwargs)
  File "drone_communication.py", line 147, in read_and_send_data
    print("Alt:",_location.alt)
NameError: name '_location' is not defined
2020-08-04 13:07:36,043 : ERROR :: Job "read_and_send_data (trigger: interval[0:00:01], next run at: 2020-08-04 13:07:37 +0545)" raised an exception
Traceback (most recent call last):
  File "/home/abhish/anaconda3/envs/xbee/lib/python3.6/site-packages/apscheduler/executors/base.py", line 125, in run_job
    retval = job.func(*job.args, **job.kwargs)
  File "drone_communication.py", line 147, in read_and_send_data
    print("Alt:",_location.alt)
NameError: name '_location' is not defined
2020-08-04 13:07:37,043 : ERROR :: Job "read_and_send_data (trigger: interval[0:00:01], next run at: 2020-08-04 13:07:38 +0545)" raised an exception
Traceback (most recent call last):
  File "/home/abhish/anaconda3/envs/xbee/lib/python3.6/site-packages/apscheduler/executors/base.py", line 125, in run_job
    retval = job.func(*job.args, **job.kwargs)
  File "drone_communication.py", line 147, in read_and_send_data
    print("Alt:",_location.alt)
NameError: name '_location' is not defined
2020-08-04 13:07:38,044 : ERROR :: Job "read_and_send_data (trigger: interval[0:00:01], next run at: 2020-08-04 13:07:39 +0545)" raised an exception
Traceback (most recent call last):
  File "/home/abhish/anaconda3/envs/xbee/lib/python3.6/site-packages/apscheduler/executors/base.py", line 125, in run_job
    retval = job.func(*job.args, **job.kwargs)
  File "drone_communication.py", line 147, in read_and_send_data
    print("Alt:",_location.alt)
NameError: name '_location' is not defined
2020-08-04 13:07:39,044 : ERROR :: Job "read_and_send_data (trigger: interval[0:00:01], next run at: 2020-08-04 13:07:40 +0545)" raised an exception
Traceback (most recent call last):
  File "/home/abhish/anaconda3/envs/xbee/lib/python3.6/site-packages/apscheduler/executors/base.py", line 125, in run_job
    retval = job.func(*job.args, **job.kwargs)
  File "drone_communication.py", line 147, in read_and_send_data
    print("Alt:",_location.alt)
NameError: name '_location' is not defined
2020-08-04 13:07:40,044 : ERROR :: Job "read_and_send_data (trigger: interval[0:00:01], next run at: 2020-08-04 13:07:41 +0545)" raised an exception
Traceback (most recent call last):
  File "/home/abhish/anaconda3/envs/xbee/lib/python3.6/site-packages/apscheduler/executors/base.py", line 125, in run_job
    retval = job.func(*job.args, **job.kwargs)
  File "drone_communication.py", line 147, in read_and_send_data
    print("Alt:",_location.alt)
NameError: name '_location' is not defined
2020-08-04 13:07:41,044 : ERROR :: Job "read_and_send_data (trigger: interval[0:00:01], next run at: 2020-08-04 13:07:42 +0545)" raised an exception
Traceback (most recent call last):
  File "/home/abhish/anaconda3/envs/xbee/lib/python3.6/site-packages/apscheduler/executors/base.py", line 125, in run_job
    retval = job.func(*job.args, **job.kwargs)
  File "drone_communication.py", line 147, in read_and_send_data
    print("Alt:",_location.alt)
NameError: name '_location' is not defined
2020-08-04 13:07:42,044 : ERROR :: Job "read_and_send_data (trigger: interval[0:00:01], next run at: 2020-08-04 13:07:43 +0545)" raised an exception
Traceback (most recent call last):
  File "/home/abhish/anaconda3/envs/xbee/lib/python3.6/site-packages/apscheduler/executors/base.py", line 125, in run_job
    retval = job.func(*job.args, **job.kwargs)
  File "drone_communication.py", line 147, in read_and_send_data
    print("Alt:",_location.alt)
NameError: name '_location' is not defined
2020-08-04 13:07:43,044 : ERROR :: Job "read_and_send_data (trigger: interval[0:00:01], next run at: 2020-08-04 13:07:44 +0545)" raised an exception
Traceback (most recent call last):
  File "/home/abhish/anaconda3/envs/xbee/lib/python3.6/site-packages/apscheduler/executors/base.py", line 125, in run_job
    retval = job.func(*job.args, **job.kwargs)
  File "drone_communication.py", line 147, in read_and_send_data
    print("Alt:",_location.alt)
NameError: name '_location' is not defined
2020-08-04 13:07:44,044 : ERROR :: Job "read_and_send_data (trigger: interval[0:00:01], next run at: 2020-08-04 13:07:45 +0545)" raised an exception
Traceback (most recent call last):
  File "/home/abhish/anaconda3/envs/xbee/lib/python3.6/site-packages/apscheduler/executors/base.py", line 125, in run_job
    retval = job.func(*job.args, **job.kwargs)
  File "drone_communication.py", line 147, in read_and_send_data
    print("Alt:",_location.alt)
NameError: name '_location' is not defined
2020-08-04 13:07:45,043 : ERROR :: Job "read_and_send_data (trigger: interval[0:00:01], next run at: 2020-08-04 13:07:46 +0545)" raised an exception
Traceback (most recent call last):
  File "/home/abhish/anaconda3/envs/xbee/lib/python3.6/site-packages/apscheduler/executors/base.py", line 125, in run_job
    retval = job.func(*job.args, **job.kwargs)
  File "drone_communication.py", line 147, in read_and_send_data
    print("Alt:",_location.alt)
NameError: name '_location' is not defined
2020-08-04 13:07:46,043 : ERROR :: Job "read_and_send_data (trigger: interval[0:00:01], next run at: 2020-08-04 13:07:47 +0545)" raised an exception
Traceback (most recent call last):
  File "/home/abhish/anaconda3/envs/xbee/lib/python3.6/site-packages/apscheduler/executors/base.py", line 125, in run_job
    retval = job.func(*job.args, **job.kwargs)
  File "drone_communication.py", line 147, in read_and_send_data
    print("Alt:",_location.alt)
NameError: name '_location' is not defined
2020-08-04 13:07:47,044 : ERROR :: Job "read_and_send_data (trigger: interval[0:00:01], next run at: 2020-08-04 13:07:48 +0545)" raised an exception
Traceback (most recent call last):
  File "/home/abhish/anaconda3/envs/xbee/lib/python3.6/site-packages/apscheduler/executors/base.py", line 125, in run_job
    retval = job.func(*job.args, **job.kwargs)
  File "drone_communication.py", line 147, in read_and_send_data
    print("Alt:",_location.alt)
NameError: name '_location' is not defined
2020-08-04 13:07:48,044 : ERROR :: Job "read_and_send_data (trigger: interval[0:00:01], next run at: 2020-08-04 13:07:49 +0545)" raised an exception
Traceback (most recent call last):
  File "/home/abhish/anaconda3/envs/xbee/lib/python3.6/site-packages/apscheduler/executors/base.py", line 125, in run_job
    retval = job.func(*job.args, **job.kwargs)
  File "drone_communication.py", line 147, in read_and_send_data
    print("Alt:",_location.alt)
NameError: name '_location' is not defined
2020-08-04 13:07:49,044 : ERROR :: Job "read_and_send_data (trigger: interval[0:00:01], next run at: 2020-08-04 13:07:50 +0545)" raised an exception
Traceback (most recent call last):
  File "/home/abhish/anaconda3/envs/xbee/lib/python3.6/site-packages/apscheduler/executors/base.py", line 125, in run_job
    retval = job.func(*job.args, **job.kwargs)
  File "drone_communication.py", line 147, in read_and_send_data
    print("Alt:",_location.alt)
NameError: name '_location' is not defined
2020-08-04 13:07:50,043 : ERROR :: Job "read_and_send_data (trigger: interval[0:00:01], next run at: 2020-08-04 13:07:51 +0545)" raised an exception
Traceback (most recent call last):
  File "/home/abhish/anaconda3/envs/xbee/lib/python3.6/site-packages/apscheduler/executors/base.py", line 125, in run_job
    retval = job.func(*job.args, **job.kwargs)
  File "drone_communication.py", line 147, in read_and_send_data
    print("Alt:",_location.alt)
NameError: name '_location' is not defined
2020-08-04 13:07:51,043 : ERROR :: Job "read_and_send_data (trigger: interval[0:00:01], next run at: 2020-08-04 13:07:52 +0545)" raised an exception
Traceback (most recent call last):
  File "/home/abhish/anaconda3/envs/xbee/lib/python3.6/site-packages/apscheduler/executors/base.py", line 125, in run_job
    retval = job.func(*job.args, **job.kwargs)
  File "drone_communication.py", line 147, in read_and_send_data
    print("Alt:",_location.alt)
NameError: name '_location' is not defined
2020-08-04 13:07:52,043 : ERROR :: Job "read_and_send_data (trigger: interval[0:00:01], next run at: 2020-08-04 13:07:53 +0545)" raised an exception
Traceback (most recent call last):
  File "/home/abhish/anaconda3/envs/xbee/lib/python3.6/site-packages/apscheduler/executors/base.py", line 125, in run_job
    retval = job.func(*job.args, **job.kwargs)
  File "drone_communication.py", line 147, in read_and_send_data
    print("Alt:",_location.alt)
NameError: name '_location' is not defined
2020-08-04 13:07:53,044 : ERROR :: Job "read_and_send_data (trigger: interval[0:00:01], next run at: 2020-08-04 13:07:54 +0545)" raised an exception
Traceback (most recent call last):
  File "/home/abhish/anaconda3/envs/xbee/lib/python3.6/site-packages/apscheduler/executors/base.py", line 125, in run_job
    retval = job.func(*job.args, **job.kwargs)
  File "drone_communication.py", line 147, in read_and_send_data
    print("Alt:",_location.alt)
NameError: name '_location' is not defined
2020-08-04 13:07:54,044 : ERROR :: Job "read_and_send_data (trigger: interval[0:00:01], next run at: 2020-08-04 13:07:55 +0545)" raised an exception
Traceback (most recent call last):
  File "/home/abhish/anaconda3/envs/xbee/lib/python3.6/site-packages/apscheduler/executors/base.py", line 125, in run_job
    retval = job.func(*job.args, **job.kwargs)
  File "drone_communication.py", line 147, in read_and_send_data
    print("Alt:",_location.alt)
NameError: name '_location' is not defined
2020-08-04 13:07:55,044 : ERROR :: Job "read_and_send_data (trigger: interval[0:00:01], next run at: 2020-08-04 13:07:56 +0545)" raised an exception
Traceback (most recent call last):
  File "/home/abhish/anaconda3/envs/xbee/lib/python3.6/site-packages/apscheduler/executors/base.py", line 125, in run_job
    retval = job.func(*job.args, **job.kwargs)
  File "drone_communication.py", line 147, in read_and_send_data
    print("Alt:",_location.alt)
NameError: name '_location' is not defined
2020-08-04 13:07:56,043 : ERROR :: Job "read_and_send_data (trigger: interval[0:00:01], next run at: 2020-08-04 13:07:57 +0545)" raised an exception
Traceback (most recent call last):
  File "/home/abhish/anaconda3/envs/xbee/lib/python3.6/site-packages/apscheduler/executors/base.py", line 125, in run_job
    retval = job.func(*job.args, **job.kwargs)
  File "drone_communication.py", line 147, in read_and_send_data
    print("Alt:",_location.alt)
NameError: name '_location' is not defined
2020-08-04 13:07:57,043 : ERROR :: Job "read_and_send_data (trigger: interval[0:00:01], next run at: 2020-08-04 13:07:58 +0545)" raised an exception
Traceback (most recent call last):
  File "/home/abhish/anaconda3/envs/xbee/lib/python3.6/site-packages/apscheduler/executors/base.py", line 125, in run_job
    retval = job.func(*job.args, **job.kwargs)
  File "drone_communication.py", line 147, in read_and_send_data
    print("Alt:",_location.alt)
NameError: name '_location' is not defined
2020-08-04 13:07:58,044 : ERROR :: Job "read_and_send_data (trigger: interval[0:00:01], next run at: 2020-08-04 13:07:59 +0545)" raised an exception
Traceback (most recent call last):
  File "/home/abhish/anaconda3/envs/xbee/lib/python3.6/site-packages/apscheduler/executors/base.py", line 125, in run_job
    retval = job.func(*job.args, **job.kwargs)
  File "drone_communication.py", line 147, in read_and_send_data
    print("Alt:",_location.alt)
NameError: name '_location' is not defined
2020-08-04 13:07:59,044 : ERROR :: Job "read_and_send_data (trigger: interval[0:00:01], next run at: 2020-08-04 13:08:00 +0545)" raised an exception
Traceback (most recent call last):
  File "/home/abhish/anaconda3/envs/xbee/lib/python3.6/site-packages/apscheduler/executors/base.py", line 125, in run_job
    retval = job.func(*job.args, **job.kwargs)
  File "drone_communication.py", line 147, in read_and_send_data
    print("Alt:",_location.alt)
NameError: name '_location' is not defined
2020-08-04 13:08:00,044 : ERROR :: Job "read_and_send_data (trigger: interval[0:00:01], next run at: 2020-08-04 13:08:01 +0545)" raised an exception
Traceback (most recent call last):
  File "/home/abhish/anaconda3/envs/xbee/lib/python3.6/site-packages/apscheduler/executors/base.py", line 125, in run_job
    retval = job.func(*job.args, **job.kwargs)
  File "drone_communication.py", line 147, in read_and_send_data
    print("Alt:",_location.alt)
NameError: name '_location' is not defined
2020-08-04 13:08:01,045 : ERROR :: Job "read_and_send_data (trigger: interval[0:00:01], next run at: 2020-08-04 13:08:02 +0545)" raised an exception
Traceback (most recent call last):
  File "/home/abhish/anaconda3/envs/xbee/lib/python3.6/site-packages/apscheduler/executors/base.py", line 125, in run_job
    retval = job.func(*job.args, **job.kwargs)
  File "drone_communication.py", line 147, in read_and_send_data
    print("Alt:",_location.alt)
NameError: name '_location' is not defined
2020-08-04 13:08:02,044 : ERROR :: Job "read_and_send_data (trigger: interval[0:00:01], next run at: 2020-08-04 13:08:03 +0545)" raised an exception
Traceback (most recent call last):
  File "/home/abhish/anaconda3/envs/xbee/lib/python3.6/site-packages/apscheduler/executors/base.py", line 125, in run_job
    retval = job.func(*job.args, **job.kwargs)
  File "drone_communication.py", line 147, in read_and_send_data
    print("Alt:",_location.alt)
NameError: name '_location' is not defined
2020-08-04 13:08:03,043 : ERROR :: Job "read_and_send_data (trigger: interval[0:00:01], next run at: 2020-08-04 13:08:04 +0545)" raised an exception
Traceback (most recent call last):
  File "/home/abhish/anaconda3/envs/xbee/lib/python3.6/site-packages/apscheduler/executors/base.py", line 125, in run_job
    retval = job.func(*job.args, **job.kwargs)
  File "drone_communication.py", line 147, in read_and_send_data
    print("Alt:",_location.alt)
NameError: name '_location' is not defined
2020-08-04 13:08:04,043 : ERROR :: Job "read_and_send_data (trigger: interval[0:00:01], next run at: 2020-08-04 13:08:05 +0545)" raised an exception
Traceback (most recent call last):
  File "/home/abhish/anaconda3/envs/xbee/lib/python3.6/site-packages/apscheduler/executors/base.py", line 125, in run_job
    retval = job.func(*job.args, **job.kwargs)
  File "drone_communication.py", line 147, in read_and_send_data
    print("Alt:",_location.alt)
NameError: name '_location' is not defined
2020-08-04 13:08:05,044 : ERROR :: Job "read_and_send_data (trigger: interval[0:00:01], next run at: 2020-08-04 13:08:06 +0545)" raised an exception
Traceback (most recent call last):
  File "/home/abhish/anaconda3/envs/xbee/lib/python3.6/site-packages/apscheduler/executors/base.py", line 125, in run_job
    retval = job.func(*job.args, **job.kwargs)
  File "drone_communication.py", line 147, in read_and_send_data
    print("Alt:",_location.alt)
NameError: name '_location' is not defined
2020-08-04 13:08:06,044 : ERROR :: Job "read_and_send_data (trigger: interval[0:00:01], next run at: 2020-08-04 13:08:07 +0545)" raised an exception
Traceback (most recent call last):
  File "/home/abhish/anaconda3/envs/xbee/lib/python3.6/site-packages/apscheduler/executors/base.py", line 125, in run_job
    retval = job.func(*job.args, **job.kwargs)
  File "drone_communication.py", line 147, in read_and_send_data
    print("Alt:",_location.alt)
NameError: name '_location' is not defined
2020-08-04 13:08:07,045 : ERROR :: Job "read_and_send_data (trigger: interval[0:00:01], next run at: 2020-08-04 13:08:08 +0545)" raised an exception
Traceback (most recent call last):
  File "/home/abhish/anaconda3/envs/xbee/lib/python3.6/site-packages/apscheduler/executors/base.py", line 125, in run_job
    retval = job.func(*job.args, **job.kwargs)
  File "drone_communication.py", line 147, in read_and_send_data
    print("Alt:",_location.alt)
NameError: name '_location' is not defined
2020-08-04 13:08:08,043 : ERROR :: Job "read_and_send_data (trigger: interval[0:00:01], next run at: 2020-08-04 13:08:09 +0545)" raised an exception
Traceback (most recent call last):
  File "/home/abhish/anaconda3/envs/xbee/lib/python3.6/site-packages/apscheduler/executors/base.py", line 125, in run_job
    retval = job.func(*job.args, **job.kwargs)
  File "drone_communication.py", line 147, in read_and_send_data
    print("Alt:",_location.alt)
NameError: name '_location' is not defined
2020-08-04 13:08:09,043 : ERROR :: Job "read_and_send_data (trigger: interval[0:00:01], next run at: 2020-08-04 13:08:10 +0545)" raised an exception
Traceback (most recent call last):
  File "/home/abhish/anaconda3/envs/xbee/lib/python3.6/site-packages/apscheduler/executors/base.py", line 125, in run_job
    retval = job.func(*job.args, **job.kwargs)
  File "drone_communication.py", line 147, in read_and_send_data
    print("Alt:",_location.alt)
NameError: name '_location' is not defined
2020-08-04 13:08:10,044 : ERROR :: Job "read_and_send_data (trigger: interval[0:00:01], next run at: 2020-08-04 13:08:11 +0545)" raised an exception
Traceback (most recent call last):
  File "/home/abhish/anaconda3/envs/xbee/lib/python3.6/site-packages/apscheduler/executors/base.py", line 125, in run_job
    retval = job.func(*job.args, **job.kwargs)
  File "drone_communication.py", line 147, in read_and_send_data
    print("Alt:",_location.alt)
NameError: name '_location' is not defined
2020-08-04 13:08:11,044 : ERROR :: Job "read_and_send_data (trigger: interval[0:00:01], next run at: 2020-08-04 13:08:12 +0545)" raised an exception
Traceback (most recent call last):
  File "/home/abhish/anaconda3/envs/xbee/lib/python3.6/site-packages/apscheduler/executors/base.py", line 125, in run_job
    retval = job.func(*job.args, **job.kwargs)
  File "drone_communication.py", line 147, in read_and_send_data
    print("Alt:",_location.alt)
NameError: name '_location' is not defined
2020-08-04 13:08:12,044 : ERROR :: Job "read_and_send_data (trigger: interval[0:00:01], next run at: 2020-08-04 13:08:13 +0545)" raised an exception
Traceback (most recent call last):
  File "/home/abhish/anaconda3/envs/xbee/lib/python3.6/site-packages/apscheduler/executors/base.py", line 125, in run_job
    retval = job.func(*job.args, **job.kwargs)
  File "drone_communication.py", line 147, in read_and_send_data
    print("Alt:",_location.alt)
NameError: name '_location' is not defined
2020-08-04 13:08:13,043 : ERROR :: Job "read_and_send_data (trigger: interval[0:00:01], next run at: 2020-08-04 13:08:14 +0545)" raised an exception
Traceback (most recent call last):
  File "/home/abhish/anaconda3/envs/xbee/lib/python3.6/site-packages/apscheduler/executors/base.py", line 125, in run_job
    retval = job.func(*job.args, **job.kwargs)
  File "drone_communication.py", line 147, in read_and_send_data
    print("Alt:",_location.alt)
NameError: name '_location' is not defined
2020-08-04 13:08:14,043 : ERROR :: Job "read_and_send_data (trigger: interval[0:00:01], next run at: 2020-08-04 13:08:15 +0545)" raised an exception
Traceback (most recent call last):
  File "/home/abhish/anaconda3/envs/xbee/lib/python3.6/site-packages/apscheduler/executors/base.py", line 125, in run_job
    retval = job.func(*job.args, **job.kwargs)
  File "drone_communication.py", line 147, in read_and_send_data
    print("Alt:",_location.alt)
NameError: name '_location' is not defined
2020-08-04 13:08:15,045 : ERROR :: Job "read_and_send_data (trigger: interval[0:00:01], next run at: 2020-08-04 13:08:16 +0545)" raised an exception
Traceback (most recent call last):
  File "/home/abhish/anaconda3/envs/xbee/lib/python3.6/site-packages/apscheduler/executors/base.py", line 125, in run_job
    retval = job.func(*job.args, **job.kwargs)
  File "drone_communication.py", line 147, in read_and_send_data
    print("Alt:",_location.alt)
NameError: name '_location' is not defined
2020-08-04 13:08:16,044 : ERROR :: Job "read_and_send_data (trigger: interval[0:00:01], next run at: 2020-08-04 13:08:17 +0545)" raised an exception
Traceback (most recent call last):
  File "/home/abhish/anaconda3/envs/xbee/lib/python3.6/site-packages/apscheduler/executors/base.py", line 125, in run_job
    retval = job.func(*job.args, **job.kwargs)
  File "drone_communication.py", line 147, in read_and_send_data
    print("Alt:",_location.alt)
NameError: name '_location' is not defined
2020-08-04 13:08:17,044 : ERROR :: Job "read_and_send_data (trigger: interval[0:00:01], next run at: 2020-08-04 13:08:18 +0545)" raised an exception
Traceback (most recent call last):
  File "/home/abhish/anaconda3/envs/xbee/lib/python3.6/site-packages/apscheduler/executors/base.py", line 125, in run_job
    retval = job.func(*job.args, **job.kwargs)
  File "drone_communication.py", line 147, in read_and_send_data
    print("Alt:",_location.alt)
NameError: name '_location' is not defined
2020-08-04 13:08:18,044 : ERROR :: Job "read_and_send_data (trigger: interval[0:00:01], next run at: 2020-08-04 13:08:19 +0545)" raised an exception
Traceback (most recent call last):
  File "/home/abhish/anaconda3/envs/xbee/lib/python3.6/site-packages/apscheduler/executors/base.py", line 125, in run_job
    retval = job.func(*job.args, **job.kwargs)
  File "drone_communication.py", line 147, in read_and_send_data
    print("Alt:",_location.alt)
NameError: name '_location' is not defined
2020-08-04 13:08:19,044 : ERROR :: Job "read_and_send_data (trigger: interval[0:00:01], next run at: 2020-08-04 13:08:20 +0545)" raised an exception
Traceback (most recent call last):
  File "/home/abhish/anaconda3/envs/xbee/lib/python3.6/site-packages/apscheduler/executors/base.py", line 125, in run_job
    retval = job.func(*job.args, **job.kwargs)
  File "drone_communication.py", line 147, in read_and_send_data
    print("Alt:",_location.alt)
NameError: name '_location' is not defined
2020-08-04 13:08:20,045 : ERROR :: Job "read_and_send_data (trigger: interval[0:00:01], next run at: 2020-08-04 13:08:21 +0545)" raised an exception
Traceback (most recent call last):
  File "/home/abhish/anaconda3/envs/xbee/lib/python3.6/site-packages/apscheduler/executors/base.py", line 125, in run_job
    retval = job.func(*job.args, **job.kwargs)
  File "drone_communication.py", line 147, in read_and_send_data
    print("Alt:",_location.alt)
NameError: name '_location' is not defined
2020-08-04 13:08:21,044 : ERROR :: Job "read_and_send_data (trigger: interval[0:00:01], next run at: 2020-08-04 13:08:22 +0545)" raised an exception
Traceback (most recent call last):
  File "/home/abhish/anaconda3/envs/xbee/lib/python3.6/site-packages/apscheduler/executors/base.py", line 125, in run_job
    retval = job.func(*job.args, **job.kwargs)
  File "drone_communication.py", line 147, in read_and_send_data
    print("Alt:",_location.alt)
NameError: name '_location' is not defined
2020-08-04 13:08:22,044 : ERROR :: Job "read_and_send_data (trigger: interval[0:00:01], next run at: 2020-08-04 13:08:23 +0545)" raised an exception
Traceback (most recent call last):
  File "/home/abhish/anaconda3/envs/xbee/lib/python3.6/site-packages/apscheduler/executors/base.py", line 125, in run_job
    retval = job.func(*job.args, **job.kwargs)
  File "drone_communication.py", line 147, in read_and_send_data
    print("Alt:",_location.alt)
NameError: name '_location' is not defined
2020-08-04 13:08:23,044 : ERROR :: Job "read_and_send_data (trigger: interval[0:00:01], next run at: 2020-08-04 13:08:24 +0545)" raised an exception
Traceback (most recent call last):
  File "/home/abhish/anaconda3/envs/xbee/lib/python3.6/site-packages/apscheduler/executors/base.py", line 125, in run_job
    retval = job.func(*job.args, **job.kwargs)
  File "drone_communication.py", line 147, in read_and_send_data
    print("Alt:",_location.alt)
NameError: name '_location' is not defined
2020-08-04 13:08:24,044 : ERROR :: Job "read_and_send_data (trigger: interval[0:00:01], next run at: 2020-08-04 13:08:25 +0545)" raised an exception
Traceback (most recent call last):
  File "/home/abhish/anaconda3/envs/xbee/lib/python3.6/site-packages/apscheduler/executors/base.py", line 125, in run_job
    retval = job.func(*job.args, **job.kwargs)
  File "drone_communication.py", line 147, in read_and_send_data
    print("Alt:",_location.alt)
NameError: name '_location' is not defined
2020-08-04 13:08:25,044 : ERROR :: Job "read_and_send_data (trigger: interval[0:00:01], next run at: 2020-08-04 13:08:26 +0545)" raised an exception
Traceback (most recent call last):
  File "/home/abhish/anaconda3/envs/xbee/lib/python3.6/site-packages/apscheduler/executors/base.py", line 125, in run_job
    retval = job.func(*job.args, **job.kwargs)
  File "drone_communication.py", line 147, in read_and_send_data
    print("Alt:",_location.alt)
NameError: name '_location' is not defined
2020-08-04 13:08:26,045 : ERROR :: Job "read_and_send_data (trigger: interval[0:00:01], next run at: 2020-08-04 13:08:27 +0545)" raised an exception
Traceback (most recent call last):
  File "/home/abhish/anaconda3/envs/xbee/lib/python3.6/site-packages/apscheduler/executors/base.py", line 125, in run_job
    retval = job.func(*job.args, **job.kwargs)
  File "drone_communication.py", line 147, in read_and_send_data
    print("Alt:",_location.alt)
NameError: name '_location' is not defined
2020-08-04 13:08:27,043 : ERROR :: Job "read_and_send_data (trigger: interval[0:00:01], next run at: 2020-08-04 13:08:28 +0545)" raised an exception
Traceback (most recent call last):
  File "/home/abhish/anaconda3/envs/xbee/lib/python3.6/site-packages/apscheduler/executors/base.py", line 125, in run_job
    retval = job.func(*job.args, **job.kwargs)
  File "drone_communication.py", line 147, in read_and_send_data
    print("Alt:",_location.alt)
NameError: name '_location' is not defined
2020-08-04 13:08:28,044 : ERROR :: Job "read_and_send_data (trigger: interval[0:00:01], next run at: 2020-08-04 13:08:29 +0545)" raised an exception
Traceback (most recent call last):
  File "/home/abhish/anaconda3/envs/xbee/lib/python3.6/site-packages/apscheduler/executors/base.py", line 125, in run_job
    retval = job.func(*job.args, **job.kwargs)
  File "drone_communication.py", line 147, in read_and_send_data
    print("Alt:",_location.alt)
NameError: name '_location' is not defined
2020-08-04 13:08:29,044 : ERROR :: Job "read_and_send_data (trigger: interval[0:00:01], next run at: 2020-08-04 13:08:30 +0545)" raised an exception
Traceback (most recent call last):
  File "/home/abhish/anaconda3/envs/xbee/lib/python3.6/site-packages/apscheduler/executors/base.py", line 125, in run_job
    retval = job.func(*job.args, **job.kwargs)
  File "drone_communication.py", line 147, in read_and_send_data
    print("Alt:",_location.alt)
NameError: name '_location' is not defined
2020-08-04 13:08:30,044 : ERROR :: Job "read_and_send_data (trigger: interval[0:00:01], next run at: 2020-08-04 13:08:31 +0545)" raised an exception
Traceback (most recent call last):
  File "/home/abhish/anaconda3/envs/xbee/lib/python3.6/site-packages/apscheduler/executors/base.py", line 125, in run_job
    retval = job.func(*job.args, **job.kwargs)
  File "drone_communication.py", line 147, in read_and_send_data
    print("Alt:",_location.alt)
NameError: name '_location' is not defined
2020-08-04 13:08:31,044 : ERROR :: Job "read_and_send_data (trigger: interval[0:00:01], next run at: 2020-08-04 13:08:32 +0545)" raised an exception
Traceback (most recent call last):
  File "/home/abhish/anaconda3/envs/xbee/lib/python3.6/site-packages/apscheduler/executors/base.py", line 125, in run_job
    retval = job.func(*job.args, **job.kwargs)
  File "drone_communication.py", line 147, in read_and_send_data
    print("Alt:",_location.alt)
NameError: name '_location' is not defined
2020-08-04 13:08:32,043 : ERROR :: Job "read_and_send_data (trigger: interval[0:00:01], next run at: 2020-08-04 13:08:33 +0545)" raised an exception
Traceback (most recent call last):
  File "/home/abhish/anaconda3/envs/xbee/lib/python3.6/site-packages/apscheduler/executors/base.py", line 125, in run_job
    retval = job.func(*job.args, **job.kwargs)
  File "drone_communication.py", line 147, in read_and_send_data
    print("Alt:",_location.alt)
NameError: name '_location' is not defined
2020-08-04 13:08:33,043 : ERROR :: Job "read_and_send_data (trigger: interval[0:00:01], next run at: 2020-08-04 13:08:34 +0545)" raised an exception
Traceback (most recent call last):
  File "/home/abhish/anaconda3/envs/xbee/lib/python3.6/site-packages/apscheduler/executors/base.py", line 125, in run_job
    retval = job.func(*job.args, **job.kwargs)
  File "drone_communication.py", line 147, in read_and_send_data
    print("Alt:",_location.alt)
NameError: name '_location' is not defined
2020-08-04 13:08:34,043 : ERROR :: Job "read_and_send_data (trigger: interval[0:00:01], next run at: 2020-08-04 13:08:35 +0545)" raised an exception
Traceback (most recent call last):
  File "/home/abhish/anaconda3/envs/xbee/lib/python3.6/site-packages/apscheduler/executors/base.py", line 125, in run_job
    retval = job.func(*job.args, **job.kwargs)
  File "drone_communication.py", line 147, in read_and_send_data
    print("Alt:",_location.alt)
NameError: name '_location' is not defined
2020-08-04 13:08:35,044 : ERROR :: Job "read_and_send_data (trigger: interval[0:00:01], next run at: 2020-08-04 13:08:36 +0545)" raised an exception
Traceback (most recent call last):
  File "/home/abhish/anaconda3/envs/xbee/lib/python3.6/site-packages/apscheduler/executors/base.py", line 125, in run_job
    retval = job.func(*job.args, **job.kwargs)
  File "drone_communication.py", line 147, in read_and_send_data
    print("Alt:",_location.alt)
NameError: name '_location' is not defined
2020-08-04 13:08:36,044 : ERROR :: Job "read_and_send_data (trigger: interval[0:00:01], next run at: 2020-08-04 13:08:37 +0545)" raised an exception
Traceback (most recent call last):
  File "/home/abhish/anaconda3/envs/xbee/lib/python3.6/site-packages/apscheduler/executors/base.py", line 125, in run_job
    retval = job.func(*job.args, **job.kwargs)
  File "drone_communication.py", line 147, in read_and_send_data
    print("Alt:",_location.alt)
NameError: name '_location' is not defined
2020-08-04 13:08:37,045 : ERROR :: Job "read_and_send_data (trigger: interval[0:00:01], next run at: 2020-08-04 13:08:38 +0545)" raised an exception
Traceback (most recent call last):
  File "/home/abhish/anaconda3/envs/xbee/lib/python3.6/site-packages/apscheduler/executors/base.py", line 125, in run_job
    retval = job.func(*job.args, **job.kwargs)
  File "drone_communication.py", line 147, in read_and_send_data
    print("Alt:",_location.alt)
NameError: name '_location' is not defined
2020-08-04 13:08:38,044 : ERROR :: Job "read_and_send_data (trigger: interval[0:00:01], next run at: 2020-08-04 13:08:39 +0545)" raised an exception
Traceback (most recent call last):
  File "/home/abhish/anaconda3/envs/xbee/lib/python3.6/site-packages/apscheduler/executors/base.py", line 125, in run_job
    retval = job.func(*job.args, **job.kwargs)
  File "drone_communication.py", line 147, in read_and_send_data
    print("Alt:",_location.alt)
NameError: name '_location' is not defined
2020-08-04 13:08:39,044 : ERROR :: Job "read_and_send_data (trigger: interval[0:00:01], next run at: 2020-08-04 13:08:40 +0545)" raised an exception
Traceback (most recent call last):
  File "/home/abhish/anaconda3/envs/xbee/lib/python3.6/site-packages/apscheduler/executors/base.py", line 125, in run_job
    retval = job.func(*job.args, **job.kwargs)
  File "drone_communication.py", line 147, in read_and_send_data
    print("Alt:",_location.alt)
NameError: name '_location' is not defined
2020-08-04 13:08:40,044 : ERROR :: Job "read_and_send_data (trigger: interval[0:00:01], next run at: 2020-08-04 13:08:41 +0545)" raised an exception
Traceback (most recent call last):
  File "/home/abhish/anaconda3/envs/xbee/lib/python3.6/site-packages/apscheduler/executors/base.py", line 125, in run_job
    retval = job.func(*job.args, **job.kwargs)
  File "drone_communication.py", line 147, in read_and_send_data
    print("Alt:",_location.alt)
NameError: name '_location' is not defined
2020-08-04 13:08:41,044 : ERROR :: Job "read_and_send_data (trigger: interval[0:00:01], next run at: 2020-08-04 13:08:42 +0545)" raised an exception
Traceback (most recent call last):
  File "/home/abhish/anaconda3/envs/xbee/lib/python3.6/site-packages/apscheduler/executors/base.py", line 125, in run_job
    retval = job.func(*job.args, **job.kwargs)
  File "drone_communication.py", line 147, in read_and_send_data
    print("Alt:",_location.alt)
NameError: name '_location' is not defined
2020-08-04 13:08:42,044 : ERROR :: Job "read_and_send_data (trigger: interval[0:00:01], next run at: 2020-08-04 13:08:43 +0545)" raised an exception
Traceback (most recent call last):
  File "/home/abhish/anaconda3/envs/xbee/lib/python3.6/site-packages/apscheduler/executors/base.py", line 125, in run_job
    retval = job.func(*job.args, **job.kwargs)
  File "drone_communication.py", line 147, in read_and_send_data
    print("Alt:",_location.alt)
NameError: name '_location' is not defined
2020-08-04 13:08:43,044 : ERROR :: Job "read_and_send_data (trigger: interval[0:00:01], next run at: 2020-08-04 13:08:44 +0545)" raised an exception
Traceback (most recent call last):
  File "/home/abhish/anaconda3/envs/xbee/lib/python3.6/site-packages/apscheduler/executors/base.py", line 125, in run_job
    retval = job.func(*job.args, **job.kwargs)
  File "drone_communication.py", line 147, in read_and_send_data
    print("Alt:",_location.alt)
NameError: name '_location' is not defined
2020-08-04 13:08:44,044 : ERROR :: Job "read_and_send_data (trigger: interval[0:00:01], next run at: 2020-08-04 13:08:45 +0545)" raised an exception
Traceback (most recent call last):
  File "/home/abhish/anaconda3/envs/xbee/lib/python3.6/site-packages/apscheduler/executors/base.py", line 125, in run_job
    retval = job.func(*job.args, **job.kwargs)
  File "drone_communication.py", line 147, in read_and_send_data
    print("Alt:",_location.alt)
NameError: name '_location' is not defined
2020-08-04 13:08:45,044 : ERROR :: Job "read_and_send_data (trigger: interval[0:00:01], next run at: 2020-08-04 13:08:46 +0545)" raised an exception
Traceback (most recent call last):
  File "/home/abhish/anaconda3/envs/xbee/lib/python3.6/site-packages/apscheduler/executors/base.py", line 125, in run_job
    retval = job.func(*job.args, **job.kwargs)
  File "drone_communication.py", line 147, in read_and_send_data
    print("Alt:",_location.alt)
NameError: name '_location' is not defined
2020-08-04 13:08:46,044 : ERROR :: Job "read_and_send_data (trigger: interval[0:00:01], next run at: 2020-08-04 13:08:47 +0545)" raised an exception
Traceback (most recent call last):
  File "/home/abhish/anaconda3/envs/xbee/lib/python3.6/site-packages/apscheduler/executors/base.py", line 125, in run_job
    retval = job.func(*job.args, **job.kwargs)
  File "drone_communication.py", line 147, in read_and_send_data
    print("Alt:",_location.alt)
NameError: name '_location' is not defined
2020-08-04 13:08:47,044 : ERROR :: Job "read_and_send_data (trigger: interval[0:00:01], next run at: 2020-08-04 13:08:48 +0545)" raised an exception
Traceback (most recent call last):
  File "/home/abhish/anaconda3/envs/xbee/lib/python3.6/site-packages/apscheduler/executors/base.py", line 125, in run_job
    retval = job.func(*job.args, **job.kwargs)
  File "drone_communication.py", line 147, in read_and_send_data
    print("Alt:",_location.alt)
NameError: name '_location' is not defined
2020-08-04 13:08:48,044 : ERROR :: Job "read_and_send_data (trigger: interval[0:00:01], next run at: 2020-08-04 13:08:49 +0545)" raised an exception
Traceback (most recent call last):
  File "/home/abhish/anaconda3/envs/xbee/lib/python3.6/site-packages/apscheduler/executors/base.py", line 125, in run_job
    retval = job.func(*job.args, **job.kwargs)
  File "drone_communication.py", line 147, in read_and_send_data
    print("Alt:",_location.alt)
NameError: name '_location' is not defined
2020-08-04 13:08:49,044 : ERROR :: Job "read_and_send_data (trigger: interval[0:00:01], next run at: 2020-08-04 13:08:50 +0545)" raised an exception
Traceback (most recent call last):
  File "/home/abhish/anaconda3/envs/xbee/lib/python3.6/site-packages/apscheduler/executors/base.py", line 125, in run_job
    retval = job.func(*job.args, **job.kwargs)
  File "drone_communication.py", line 147, in read_and_send_data
    print("Alt:",_location.alt)
NameError: name '_location' is not defined
2020-08-04 13:08:50,044 : ERROR :: Job "read_and_send_data (trigger: interval[0:00:01], next run at: 2020-08-04 13:08:51 +0545)" raised an exception
Traceback (most recent call last):
  File "/home/abhish/anaconda3/envs/xbee/lib/python3.6/site-packages/apscheduler/executors/base.py", line 125, in run_job
    retval = job.func(*job.args, **job.kwargs)
  File "drone_communication.py", line 147, in read_and_send_data
    print("Alt:",_location.alt)
NameError: name '_location' is not defined
2020-08-04 13:08:51,043 : ERROR :: Job "read_and_send_data (trigger: interval[0:00:01], next run at: 2020-08-04 13:08:52 +0545)" raised an exception
Traceback (most recent call last):
  File "/home/abhish/anaconda3/envs/xbee/lib/python3.6/site-packages/apscheduler/executors/base.py", line 125, in run_job
    retval = job.func(*job.args, **job.kwargs)
  File "drone_communication.py", line 147, in read_and_send_data
    print("Alt:",_location.alt)
NameError: name '_location' is not defined
2020-08-04 13:08:52,044 : ERROR :: Job "read_and_send_data (trigger: interval[0:00:01], next run at: 2020-08-04 13:08:53 +0545)" raised an exception
Traceback (most recent call last):
  File "/home/abhish/anaconda3/envs/xbee/lib/python3.6/site-packages/apscheduler/executors/base.py", line 125, in run_job
    retval = job.func(*job.args, **job.kwargs)
  File "drone_communication.py", line 147, in read_and_send_data
    print("Alt:",_location.alt)
NameError: name '_location' is not defined
2020-08-04 13:08:53,044 : ERROR :: Job "read_and_send_data (trigger: interval[0:00:01], next run at: 2020-08-04 13:08:54 +0545)" raised an exception
Traceback (most recent call last):
  File "/home/abhish/anaconda3/envs/xbee/lib/python3.6/site-packages/apscheduler/executors/base.py", line 125, in run_job
    retval = job.func(*job.args, **job.kwargs)
  File "drone_communication.py", line 147, in read_and_send_data
    print("Alt:",_location.alt)
NameError: name '_location' is not defined
2020-08-04 13:08:54,044 : ERROR :: Job "read_and_send_data (trigger: interval[0:00:01], next run at: 2020-08-04 13:08:55 +0545)" raised an exception
Traceback (most recent call last):
  File "/home/abhish/anaconda3/envs/xbee/lib/python3.6/site-packages/apscheduler/executors/base.py", line 125, in run_job
    retval = job.func(*job.args, **job.kwargs)
  File "drone_communication.py", line 147, in read_and_send_data
    print("Alt:",_location.alt)
NameError: name '_location' is not defined
2020-08-04 13:08:55,045 : ERROR :: Job "read_and_send_data (trigger: interval[0:00:01], next run at: 2020-08-04 13:08:56 +0545)" raised an exception
Traceback (most recent call last):
  File "/home/abhish/anaconda3/envs/xbee/lib/python3.6/site-packages/apscheduler/executors/base.py", line 125, in run_job
    retval = job.func(*job.args, **job.kwargs)
  File "drone_communication.py", line 147, in read_and_send_data
    print("Alt:",_location.alt)
NameError: name '_location' is not defined
2020-08-04 13:08:56,044 : ERROR :: Job "read_and_send_data (trigger: interval[0:00:01], next run at: 2020-08-04 13:08:57 +0545)" raised an exception
Traceback (most recent call last):
  File "/home/abhish/anaconda3/envs/xbee/lib/python3.6/site-packages/apscheduler/executors/base.py", line 125, in run_job
    retval = job.func(*job.args, **job.kwargs)
  File "drone_communication.py", line 147, in read_and_send_data
    print("Alt:",_location.alt)
NameError: name '_location' is not defined
